Workbook

Sheet Method Comparison
A1: ="Verification of " &B2& " on " &B3 -> Verification of NT-proBNP on Vitros 5600
A2: Analyte: | B2: NT-proBNP
A3: Instrument: | B3: Vitros 5600
A4: Instrument S/N: | B4: 1290353
A5: Purpose: | B5: This method serves to bringing in-house BNP testing for heart failure assessments
A7: Unit of Measure: | B7: ng/L
A9: The complete evaluation consists of:
A10: 1) | B10: Precision Studies over 20 days, Running Each Level Duplicates, Across 2 Runs; Total 80 points
A11: 2) | B11: Accuracy by Method Comparison ( 20 - 40 samples minimum)
A12: 3) | B12: Linearity (See Corresponding Tab)
A13: 4) | B13: Reference Interval Verification (See Corresponding Tab) - only on recommendation from biochemist
A14: Additional Studies Include:
A19: Accuracy by Method Comparison
A20: Test Method 1: | B20: Vitros 5600
A21: Principle
A22: Reagent Lot #: | B22: #032200
A23: Calibrator Lot #: | B23: #0132
A26: Primary Reference Method: | B26: Abbott Alinity i
A27: Principle
A28: Reagent Lot# (If available from Ref Lab)
A29: Calibrator Lot# (If available from Ref Lab)
A33: Instructions
B34: Part 1
C35: Please use 20 serum (SST) and 20 EDTA plasma samples
B36: a. | C36: Please ensure the instrument is ready to report in SI units
B37: b. | C37: Ensure the lower end of the AMR is set to 0
B38: b. | C38: Ensure QC has passed for the day and instrument is in working order.
B39: c. | C39: Run equal number of patient samples over the course of 5 days on the Test Method and Reference Method
B40: d. | C40: Jot down the results table below.
B41: Note: | C41: If calibrator or reagent lot number changes during course of study, please make note of this in the comment column
A44: Matrix (U/S) | B44: Sample No. | C44: Sample ID | D44: Primary Refence Method Result | E44: Test Method Result | F44: Tube Type (e.g. SST/EDTA) | G44: Day | H44: Comments
A45: S | B45: 1 | C45: 13212 | D45: 1485.1 | E45: 1710 | F45: SST | G45: 1
A46: S | B46: 2 | C46: 13213 | D46: 855.2 | E46: 881 | F46: SST | G46: 1
A47: S | B47: 3 | C47: 13214 | D47: 9964 | E47: 10200 | F47: SST | G47: 1
A48: S | B48: 4 | C48: 13215 | D48: 13204.8 | E48: 12700 | F48: SST | G48: 1
A49: S | B49: 5 | C49: 13216 | D49: 4948.7 | E49: 4690 | F49: SST | G49: 1
A50: S | B50: 6 | C50: 13217 | D50: 11622.3 | E50: 10900 | F50: SST | G50: 1
A51: S | B51: 7 | C51: 13218 | D51: 8807.8 | E51: 7860 | F51: SST | G51: 1
A52: S | B52: 8 | C52: 13219 | D52: 2996.8 | E52: 3150 | F52: SST | G52: 1
A53: S | B53: 9 | C53: 13220 | D53: 5692.5 | E53: 5910 | F53: SST | G53: 1
...

Sheet Precision
A1: ="Verification of " &B2& " on " &B3 -> Verification of NT-proBNP on Vitros 5600
A2: Analytes: | B2: ='Method Comparison'!B2 -> NT-proBNP
A3: Instrument: | B3: ='Method Comparison'!B3 -> Vitros 5600
A4: Instrument S/N: | B4: ='Method Comparison'!B4 -> 1290353
A5: Purpose: | B5: ='Method Comparison'!B5:F5 -> This method serves to bringing in-house BNP testing for heart failure assessments
A6: Matrix | B6: Serum
A7: Unit of Measure: | B7: ='Method Comparison'!B7 -> ng/L
B8: Instructions for Precision Studies
A10: Reagent Lot #: | B10: 32200
A11: Calibrator Lot #:
A12: QC Lot Level 1
A13: QC Lot Level 3
A14: QC Lot Level 4
A15: QC Lot Level 4 | B15: N/A
A16: a. | B16: Perform assay calibration on the first day. For each day, run each level of QC across 2 runs, each run in duplicate.
A17: b. | B17: One run ideally in the morning (Run 1) with duplicate measurements & and another in PM (Run 2).
A18: c. | B18: Indicate any calibration. Ensure there is no change in QC Lot# throughout this study.
A19: Note: | B19: Please note calibrator, reagent, or QC lot number changes
B20: Level 1 | I20: Level 3 | P20: Level 4
B21: Day | C21: Run | D21: Replicate | E21: Date | F21: Result | G21: Calibration(Y/N) | I21: Day | J21: Run | K21: Replicate | L21: Date | M21: Result | N21: Calibration(Y/N) | P21: Day | Q21: Run | R21: Replicate | S21: Date | T21: Result | U21: Calibration(Y/N)
B22: =INT((ROW()-22)/4)+1 -> 1 | C22: 1 | D22: 1 | E22: 14/1/26 | F22: 101 | G22: N | I22: 1 | J22: 1 | K22: 1 | L22: 14/1/26 | M22: 272 | N22: N | P22: 1 | Q22: 1 | R22: 1 | S22: 14/1/26 | T22: 4640 | U22: N
B23: =INT((ROW()-22)/4)+1 -> 1 | C23: 1 | D23: 2 | E23: 14/1/26 | F23: 104 | G23: N | I23: 1 | J23: 1 | K23: 2 | L23: 14/1/26 | M23: 277 | N23: N | P23: 1 | Q23: 1 | R23: 2 | S23: 14/1/26 | T23: 4690 | U23: N
B24: =INT((ROW()-22)/4)+1 -> 1 | C24: 2 | D24: 1 | E24: 14/1/26 | F24: 99.7 | G24: N | I24: 1 | J24: 2 | K24: 1 | L24: 14/1/26 | M24: 265 | N24: N | P24: 1 | Q24: 2 | R24: 1 | S24: 14/1/26 | T24: 4580 | U24: N
B25: =INT((ROW()-22)/4)+1 -> 1 | C25: 2 | D25: 2 | E25: 14/1/26 | F25: 101 | G25: N | I25: 1 | J25: 2 | K25: 2 | L25: 14/1/26 | M25: 271 | N25: N | P25: 1 | Q25: 2 | R25: 2 | S25: 14/1/26 | T25: 4680 | U25: N
B26: =INT((ROW()-22)/4)+1 -> 2 | C26: 1 | D26: 1 | E26: 15/1/26 | F26: 104 | G26: N | I26: 2 | J26: 1 | K26: 1 | L26: 15/1/26 | M26: 278 | N26: N | P26: 2 | Q26: 1 | R26: 1 | S26: 15/1/26 | T26: 4610 | U26: N
B27: =INT((ROW()-22)/4)+1 -> 2 | C27: 1 | D27: 2 | E27: 15/1/26 | F27: 102 | G27: N | I27: 2 | J27: 1 | K27: 2 | L27: 15/1/26 | M27: 266 | N27: N | P27: 2 | Q27: 1 | R27: 2 | S27: 15/1/26 | T27: 4700 | U27: N
B28: =INT((ROW()-22)/4)+1 -> 2 | C28: 2 | D28: 1 | E28: 15/1/26 | F28: 104 | G28: N | I28: 2 | J28: 2 | K28: 1 | L28: 15/1/26 | M28: 273 | N28: N | P28: 2 | Q28: 2 | R28: 1 | S28: 15/1/26 | T28: 4690 | U28: N
B29: =INT((ROW()-22)/4)+1 -> 2 | C29: 2 | D29: 2 | E29: 15/1/26 | F29: 102 | G29: N | I29: 2 | J29: 2 | K29: 2 | L29: 15/1/26 | M29: 278 | N29: N | P29: 2 | Q29: 2 | R29: 2 | S29: 15/1/26 | T29: 4710 | U29: N
B30: =INT((ROW()-22)/4)+1 -> 3 | C30: 1 | D30: 1 | E30: 16/1/26 | F30: 102 | G30: N | I30: 3 | J30: 1 | K30: 1 | L30: 16/1/26 | M30: 272 | N30: N | P30: 3 | Q30: 1 | R30: 1 | S30: 16/1/26 | T30: 4710 | U30: N
B31: =INT((ROW()-22)/4)+1 -> 3 | C31: 1 | D31: 2 | E31: 16/1/26 | F31: 100 | G31: N | I31: 3 | J31: 1 | K31: 2 | L31: 16/1/26 | M31: 276 | N31: N | P31: 3 | Q31: 1 | R31: 2 | S31: 16/1/26 | T31: 4710 | U31: N
B32: =INT((ROW()-22)/4)+1 -> 3 | C32: 2 | D32: 1 | E32: 16/1/26 | F32: 106 | G32: N | I32: 3 | J32: 2 | K32: 1 | L32: 16/1/26 | M32: 279 | N32: N | P32: 3 | Q32: 2 | R32: 1 | S32: 16/1/26 | T32: 4730 | U32: N
B33: =INT((ROW()-22)/4)+1 -> 3 | C33: 2 | D33: 2 | E33: 16/1/26 | F33: 103 | G33: N | I33: 3 | J33: 2 | K33: 2 | L33: 16/1/26 | M33: 277 | N33: N | P33: 3 | Q33: 2 | R33: 2 | S33: 16/1/26 | T33: 4630 | U33: N
... B61: =INT((ROW()-22)/4)+1 -> 10 | C61: 2 | D61: 2 | E61: 23/1/26 | F61: 105 | G61: N | I61: 10 | J61: 2 | K61: 2 | L61: 23/1/26 | M61: 274 | N61: N | P61: 10 | Q61: 2 | R61: 2 | S61: 23/1/26 | T61: 4710 | U61: N
B62: =INT((ROW()-22)/4)+1 -> 11 | C62: 1 | D62: 1 | E62: 46328 | F62: 102 | G62: Y new lot# 032250 | I62: 11 | J62: 1 | K62: 1 | L62: 46328 | M62: 269 | N62: Y new lot# 032250 | P62: 11 | Q62: 1 | R62: 1 | S62: 46328 | T62: 4580 | U62: Y new lot# 032250
B63: =INT((ROW()-22)/4)+1 -> 11 | C63: 1 | D63: 2 | E63: 46328 | F63: 100 | G63: Y new lot# 032250 | I63: 11 | J63: 1 | K63: 2 | L63: 46328 | M63: 273 | N63: Y new lot# 032250 | P63: 11 | Q63: 1 | R63: 2 | S63: 46328 | T63: 4710 | U63: Y new lot# 032250
B64: =INT((ROW()-22)/4)+1 -> 11 | C64: 2 | D64: 1 | E64: 46358 | F64: 99 | G64: N | I64: 11 | J64: 2 | K64: 1 | L64: 46358 | M64: 269 | N64: N | P64: 11 | Q64: 2 | R64: 1 | S64: 46358 | T64: 4750 | U64: N
B65: =INT((ROW()-22)/4)+1 -> 11 | C65: 2 | D65: 2 | E65: 46358 | F65: 99 | G65: N | I65: 11 | J65: 2 | K65: 2 | L65: 46358 | M65: 270 | N65: N | P65: 11 | Q65: 2 | R65: 2 | S65: 46358 | T65: 4690 | U65: N
B66: =INT((ROW()-22)/4)+1 -> 12 | C66: 1 | D66: 1 | E66: 15/2/26 | F66: 99 | G66: N | I66: 12 | J66: 1 | K66: 1 | L66: 15/2/26 | M66: 260 | N66: N | P66: 12 | Q66: 1 | R66: 1 | S66: 15/2/26 | T66: 4640 | U66: N
B67: =INT((ROW()-22)/4)+1 -> 12 | C67: 1 | D67: 2 | E67: 15/2/26 | F67: 98.5 | G67: N | I67: 12 | J67: 1 | K67: 2 | L67: 15/2/26 | M67: 267 | N67: N | P67: 12 | Q67: 1 | R67: 2 | S67: 15/2/26 | T67: 4630 | U67: N
B68: =INT((ROW()-22)/4)+1 -> 12 | C68: 2 | D68: 1 | E68: 16/2/26 | F68: 103 | G68: N | I68: 12 | J68: 2 | K68: 1 | L68: 16/2/26 | M68: 270 | N68: N | P68: 12 | Q68: 2 | R68: 1 | S68: 16/2/26 | T68: 4650 | U68: N
...

Sheet Linearity, Sr
A1: Linearity Study
A2: Unit of Measure: | B2: nmol/L
A3: Matrix: | B3: Serum
A5: Package Insert AMI:
A6: Extended AMI (from insert):
A7: Name of Linearity Material:
A8: Lot# :
A9: Company (e.g. CAP, Maine):
A10: NOTE: | B10: If no linearity material is commercially available, one can use a high patient pool with dilution studies.
A12: Instructions: | B12: Follow manufacturer instructions. Generally expect 3 replicates per level.
B13: If available, provide the expected mean and/or range from the manufacturer
A15: Levels | B15: Replicate | C15: Measured Result | D15: Average | E15: Expected Mean | F15: Expected Range
A16: Level 1 | B16: 1 | C16: 325.7 | D16: =AVERAGE(C16:C18) -> 322.35 | E16: 322.35
A17: Level 1 | B17: 2 | C17: 319
A18: Level 1 | B18: 3
A19: Level 2 | B19: 1 | C19: 273.5 | D19: =AVERAGE(C19:C20) -> 272.8 | E19: 290.115
A20: Level 2 | B20: 2 | C20: 272.1
A21: Level 2 | B21: 3
A22: Level 3 | B22: 1 | C22: 196.8 | D22: =AVERAGE(C22:C24) -> 196.6 | E22: 257.88
A23: Level 3 | B23: 2 | C23: 196.4
A24: Level 3 | B24: 3
A25: Level 4 | B25: 1 | C25: 169.9 | D25: =AVERAGE(C25:C27) -> 169.5 | E25: 225.65
A26: Level 4 | B26: 2 | C26: 169.1
A27: Level 4 | B27: 3
A28: Level 5 | B28: 1 | C28: 136.2 | D28: 136.2 | E28: 193.4
A29: Level 5 | B29: 2 | C29: 135.8
A30: Level 5 | B30: 3
A31: Level 6 | B31: 1 | C31: 116.1 | D31: =AVERAGE(C31:C33) -> 115.6 | E31: 161.18
A32: Level 6 | B32: 2 | C32: 115.1
A33: Level 6 | B33: 3
A34: Level 7 | B34: 1 | C34: 93.6 | D34: =AVERAGE(C34:C36) -> 94.05 | E34: 128.94
A35: Level 7 | B35: 2 | C35: 94.5
A36: Level 7 | B36: 3
A37: Level 8 | B37: 1 | C37: 71.6 | D37: =AVERAGE(C37:C39) -> 71.3 | E37: 96.71
A38: Level 8 | B38: 2 | C38: 71
A39: Level 8 | B39: 3
A40: Level 9 | B40: 1 | C40: 51.8 | D40: =AVERAGE(C40:C42) -> 50.55 | E40: 64.47
A41: Level 9 | B41: 2 | C41: 49.3
A42: Level 9 | B42: 3
A43: Level 10 | B43: 1 | C43: 27.8 | D43: =AVERAGE(C43:C45) -> 27.7 | E43: 32.235
...

Sheet Reference Interval
A1: ="Verification of " &B2& " on " &B3 -> Verification of NT-proBNP on Vitros 5600
A2: Analytes: | B2: ='Method Comparison'!B2 -> NT-proBNP
A3: Instrument: | B3: ='Method Comparison'!B3 -> Vitros 5600
A4: Instrument S/N: | B4: ='Method Comparison'!B4 -> 1290353
A5: Purpose: | B5: ='Method Comparison'!B5:F5 -> This method serves to bringing in-house BNP testing for heart failure assessments
A6: Matrix:
A7: Unit of Measure: | B7: ='Method Comparison'!B7 -> ng/L
A11: Refernece Interval (RI) Adoption Method: | D11: Selected Options (1-5):
A12: 1. Transference via Method Equivalence
A13: 2. Verification by 20 - 40 Ostensibily Health Individuals
A14: 3. Therapeutic interval from clinical input
A15: 4. Therapeutic interval from manufacturer
A16: 5. Other (Explain) | D16: Adoption of Medical Decision Points from Clinical Cut-offs
A18: Current RI:
A19: Current Source of RI:
A20: Proposed RI
A21: Proposed Source of RI:
A25: Healthy Individual # | B25: Gender | C25: Age | D25: Result | E25: Bacrode | F25: Specimen#
F26: 1
F27: 2
F28: 3
F29: 4
F30: 5
F31: 6
F32: 7
F33: 8
F34: 9
F35: 10
F36: 11
F37: 12
... F103: 78
